[2022-11-23 16:35:38,903] {taskinstance.py:1037} INFO - Dependencies all met for <TaskInstance: dag_combustivel.create_cluster scheduled__2006-07-01T00:00:00+00:00 [queued]>
[2022-11-23 16:35:38,925] {taskinstance.py:1037} INFO - Dependencies all met for <TaskInstance: dag_combustivel.create_cluster scheduled__2006-07-01T00:00:00+00:00 [queued]>
[2022-11-23 16:35:38,925] {taskinstance.py:1243} INFO - 
--------------------------------------------------------------------------------
[2022-11-23 16:35:38,926] {taskinstance.py:1244} INFO - Starting attempt 1 of 1
[2022-11-23 16:35:38,927] {taskinstance.py:1245} INFO - 
--------------------------------------------------------------------------------
[2022-11-23 16:35:38,948] {taskinstance.py:1264} INFO - Executing <Task(DataprocCreateClusterOperator): create_cluster> on 2006-07-01 00:00:00+00:00
[2022-11-23 16:35:38,955] {standard_task_runner.py:52} INFO - Started process 3728 to run task
[2022-11-23 16:35:38,963] {standard_task_runner.py:76} INFO - Running: ['***', 'tasks', 'run', 'dag_combustivel', 'create_cluster', 'scheduled__2006-07-01T00:00:00+00:00', '--job-id', '28', '--raw', '--subdir', 'DAGS_FOLDER/dag_combustivel.py', '--cfg-path', '/tmp/tmp2yn468wy', '--error-file', '/tmp/tmp0_8dfmvk']
[2022-11-23 16:35:38,965] {standard_task_runner.py:77} INFO - Job 28: Subtask create_cluster
[2022-11-23 16:35:39,075] {logging_mixin.py:109} INFO - Running <TaskInstance: dag_combustivel.create_cluster scheduled__2006-07-01T00:00:00+00:00 [running]> on host 8c4b0b632010
[2022-11-23 16:35:39,198] {taskinstance.py:1431} INFO - Exporting the following env vars:
AIRFLOW_CTX_DAG_OWNER=***
AIRFLOW_CTX_DAG_ID=dag_combustivel
AIRFLOW_CTX_TASK_ID=create_cluster
AIRFLOW_CTX_EXECUTION_DATE=2006-07-01T00:00:00+00:00
AIRFLOW_CTX_DAG_RUN_ID=scheduled__2006-07-01T00:00:00+00:00
[2022-11-23 16:35:39,200] {dataproc.py:625} INFO - Creating cluster: stack-data-pipeline
[2022-11-23 16:35:41,662] {dataproc.py:643} INFO - Cluster already exists.
[2022-11-23 16:35:42,645] {dataproc.py:589} INFO - Cluster is in ERROR state
[2022-11-23 16:35:43,740] {taskinstance.py:1718} ERROR - Task failed with exception
Traceback (most recent call last):
  File "/home/airflow/.local/lib/python3.7/site-packages/google/api_core/grpc_helpers.py", line 67, in error_remapped_callable
    return callable_(*args, **kwargs)
  File "/home/airflow/.local/lib/python3.7/site-packages/grpc/_channel.py", line 946, in __call__
    return _end_unary_response_blocking(state, call, False, None)
  File "/home/airflow/.local/lib/python3.7/site-packages/grpc/_channel.py", line 849, in _end_unary_response_blocking
    raise _InactiveRpcError(state)
grpc._channel._InactiveRpcError: <_InactiveRpcError of RPC that terminated with:
	status = StatusCode.FAILED_PRECONDITION
	details = "Detected missing master VMs!
Details: [Missing GCE VM stack-data-pipeline-m.]"
	debug_error_string = "{"created":"@1669221343.739585800","description":"Error received from peer ipv4:142.251.128.10:443","file":"src/core/lib/surface/call.cc","file_line":903,"grpc_message":"Detected missing master VMs!\nDetails: [Missing GCE VM stack-data-pipeline-m.]","grpc_status":9}"
>

The above exception was the direct cause of the following exception:

Traceback (most recent call last):
  File "/home/airflow/.local/lib/python3.7/site-packages/airflow/models/taskinstance.py", line 1334, in _run_raw_task
    self._execute_task_with_callbacks(context)
  File "/home/airflow/.local/lib/python3.7/site-packages/airflow/models/taskinstance.py", line 1460, in _execute_task_with_callbacks
    result = self._execute_task(context, self.task)
  File "/home/airflow/.local/lib/python3.7/site-packages/airflow/models/taskinstance.py", line 1516, in _execute_task
    result = execute_callable(context=context)
  File "/home/airflow/.local/lib/python3.7/site-packages/airflow/providers/google/cloud/operators/dataproc.py", line 647, in execute
    self._handle_error_state(hook, cluster)
  File "/home/airflow/.local/lib/python3.7/site-packages/airflow/providers/google/cloud/operators/dataproc.py", line 591, in _handle_error_state
    region=self.region, cluster_name=self.cluster_name, project_id=self.project_id
  File "/home/airflow/.local/lib/python3.7/site-packages/airflow/providers/google/common/hooks/base_google.py", line 433, in inner_wrapper
    return func(self, *args, **kwargs)
  File "/home/airflow/.local/lib/python3.7/site-packages/airflow/providers/google/cloud/hooks/dataproc.py", line 419, in diagnose_cluster
    metadata=metadata,
  File "/home/airflow/.local/lib/python3.7/site-packages/google/cloud/dataproc_v1/services/cluster_controller/client.py", line 1165, in diagnose_cluster
    response = rpc(request, retry=retry, timeout=timeout, metadata=metadata,)
  File "/home/airflow/.local/lib/python3.7/site-packages/google/api_core/gapic_v1/method.py", line 145, in __call__
    return wrapped_func(*args, **kwargs)
  File "/home/airflow/.local/lib/python3.7/site-packages/google/api_core/grpc_helpers.py", line 69, in error_remapped_callable
    six.raise_from(exceptions.from_grpc_error(exc), exc)
  File "<string>", line 3, in raise_from
google.api_core.exceptions.FailedPrecondition: 400 Detected missing master VMs!
Details: [Missing GCE VM stack-data-pipeline-m.]
[2022-11-23 16:35:43,783] {taskinstance.py:1282} INFO - Marking task as FAILED. dag_id=dag_combustivel, task_id=create_cluster, execution_date=20060701T000000, start_date=20221123T163538, end_date=20221123T163543
[2022-11-23 16:35:43,805] {standard_task_runner.py:92} ERROR - Failed to execute job 28 for task create_cluster
Traceback (most recent call last):
  File "/home/airflow/.local/lib/python3.7/site-packages/google/api_core/grpc_helpers.py", line 67, in error_remapped_callable
    return callable_(*args, **kwargs)
  File "/home/airflow/.local/lib/python3.7/site-packages/grpc/_channel.py", line 946, in __call__
    return _end_unary_response_blocking(state, call, False, None)
  File "/home/airflow/.local/lib/python3.7/site-packages/grpc/_channel.py", line 849, in _end_unary_response_blocking
    raise _InactiveRpcError(state)
grpc._channel._InactiveRpcError: <_InactiveRpcError of RPC that terminated with:
	status = StatusCode.FAILED_PRECONDITION
	details = "Detected missing master VMs!
Details: [Missing GCE VM stack-data-pipeline-m.]"
	debug_error_string = "{"created":"@1669221343.739585800","description":"Error received from peer ipv4:142.251.128.10:443","file":"src/core/lib/surface/call.cc","file_line":903,"grpc_message":"Detected missing master VMs!\nDetails: [Missing GCE VM stack-data-pipeline-m.]","grpc_status":9}"
>

The above exception was the direct cause of the following exception:

Traceback (most recent call last):
  File "/home/airflow/.local/lib/python3.7/site-packages/airflow/task/task_runner/standard_task_runner.py", line 85, in _start_by_fork
    args.func(args, dag=self.dag)
  File "/home/airflow/.local/lib/python3.7/site-packages/airflow/cli/cli_parser.py", line 48, in command
    return func(*args, **kwargs)
  File "/home/airflow/.local/lib/python3.7/site-packages/airflow/utils/cli.py", line 92, in wrapper
    return f(*args, **kwargs)
  File "/home/airflow/.local/lib/python3.7/site-packages/airflow/cli/commands/task_command.py", line 298, in task_run
    _run_task_by_selected_method(args, dag, ti)
  File "/home/airflow/.local/lib/python3.7/site-packages/airflow/cli/commands/task_command.py", line 107, in _run_task_by_selected_method
    _run_raw_task(args, ti)
  File "/home/airflow/.local/lib/python3.7/site-packages/airflow/cli/commands/task_command.py", line 184, in _run_raw_task
    error_file=args.error_file,
  File "/home/airflow/.local/lib/python3.7/site-packages/airflow/utils/session.py", line 70, in wrapper
    return func(*args, session=session, **kwargs)
  File "/home/airflow/.local/lib/python3.7/site-packages/airflow/models/taskinstance.py", line 1334, in _run_raw_task
    self._execute_task_with_callbacks(context)
  File "/home/airflow/.local/lib/python3.7/site-packages/airflow/models/taskinstance.py", line 1460, in _execute_task_with_callbacks
    result = self._execute_task(context, self.task)
  File "/home/airflow/.local/lib/python3.7/site-packages/airflow/models/taskinstance.py", line 1516, in _execute_task
    result = execute_callable(context=context)
  File "/home/airflow/.local/lib/python3.7/site-packages/airflow/providers/google/cloud/operators/dataproc.py", line 647, in execute
    self._handle_error_state(hook, cluster)
  File "/home/airflow/.local/lib/python3.7/site-packages/airflow/providers/google/cloud/operators/dataproc.py", line 591, in _handle_error_state
    region=self.region, cluster_name=self.cluster_name, project_id=self.project_id
  File "/home/airflow/.local/lib/python3.7/site-packages/airflow/providers/google/common/hooks/base_google.py", line 433, in inner_wrapper
    return func(self, *args, **kwargs)
  File "/home/airflow/.local/lib/python3.7/site-packages/airflow/providers/google/cloud/hooks/dataproc.py", line 419, in diagnose_cluster
    metadata=metadata,
  File "/home/airflow/.local/lib/python3.7/site-packages/google/cloud/dataproc_v1/services/cluster_controller/client.py", line 1165, in diagnose_cluster
    response = rpc(request, retry=retry, timeout=timeout, metadata=metadata,)
  File "/home/airflow/.local/lib/python3.7/site-packages/google/api_core/gapic_v1/method.py", line 145, in __call__
    return wrapped_func(*args, **kwargs)
  File "/home/airflow/.local/lib/python3.7/site-packages/google/api_core/grpc_helpers.py", line 69, in error_remapped_callable
    six.raise_from(exceptions.from_grpc_error(exc), exc)
  File "<string>", line 3, in raise_from
google.api_core.exceptions.FailedPrecondition: 400 Detected missing master VMs!
Details: [Missing GCE VM stack-data-pipeline-m.]
[2022-11-23 16:35:43,837] {local_task_job.py:154} INFO - Task exited with return code 1
[2022-11-23 16:35:43,903] {local_task_job.py:264} INFO - 0 downstream tasks scheduled from follow-on schedule check
